Workbook

Sheet TOC & Summary
A2: Polycab India Limited - 5-Year Financial Model
A5: Generated: August 2026
A7: Table of Contents
A9: Sheet Name | B9: Description
A10: TOC & Summary | B10: This tab - contains the model overview, table of contents, and formatting key.
A11: Income Statement | B11: Consolidated Income Statement for FY22 to FY26 with historical trends and margins.
A12: Balance Sheet | B12: Consolidated Balance Sheet for FY22 to FY26 with assets, liabilities, and equity details.
A13: Forensic & Ratio Analysis | B13: Forensic analysis, key performance ratios, and red flag warnings over the 5-year period.
A14: Notes to Accounts Linkages | B14: Footnote linkages connecting key Balance Sheet & Income Statement rows to their quantitative accounting notes.
A15: MD&A Strategic Analysis | B15: Longitudinal 5-year operational analysis of Polycab's segment performance, Project LEAP success, and Project Spring roadmap.
A16: ESG Performance (BRSR) | B16: Comprehensive socio-environmental and governance metrics (FY22-FY26), tracking emissions, renewable energy, circular economy, and CSR.
A17: Color / Style | B17: Role in Model
A18: Deep Blue Fill | B18: Section and Main Headers (Non-editable)
A19: Light Blue Fill | B19: Input Cells
A20: Light Green Fill | B20: Calculated / Formula-driven Cells (Autofill)
A21: Light Red/Orange Fill | B21: Forensic Red Flag / Watch Out Triggers

Sheet Income Statement
A1: Polycab India Limited
A2: Consolidated Statement of Profit and Loss (FY22 - FY26)
A4: Line Item | B4: FY22 | C4: FY23 | D4: FY24 | E4: FY25 | F4: FY26
A5: INCOME
A6: Revenue from operations | B6: 122037.61 | C6: 141077.78 | D6: 180394.44 | E6: 224083.13 | F6: 288837.92
A7: Other income | B7: 899.23 | C7: 1333.26 | D7: 2208.75 | E7: 2076.36 | F7: 2362.52
A8: Total Income | B8: =SUM(B6:B7) -> 122936.84 | C8: =SUM(C6:C7) -> 142411.04 | D8: =SUM(D6:D7) -> 182603.19 | E8: =SUM(E6:E7) -> 226159.49 | F8: =SUM(F6:F7) -> 291200.44
A10: EXPENSES
A11: Cost of materials consumed | B11: 92042.53 | C11: 97711.55 | D11: 126615.96 | E11: 154173.73 | F11: 206156.67
A12: Purchases of stock-in-trade | B12: 6427.02 | C12: 5699.12 | D12: 5658.67 | E12: 6076.37 | F12: 7314.54
A13: Changes in inventories of finished goods, WIP and scrap | B13: -4927.51 | C13: 346.76 | D13: -4215.09 | E13: -4518.64 | F13: -7601.62
A14: Project bought outs and subcontracting cost | B14: 1114.72 | C14: 1351.53 | D14: 4743.47 | E14: 12568.87 | F14: 9946.38
A15: Employee benefits expense | B15: 4066.28 | C15: 4567.72 | D15: 6095.42 | E15: 7367.26 | F15: 8794.24
A16: Finance costs | B16: 351.9 | C16: 597.57 | D16: 1083.4 | E16: 1689.28 | F16: 2430.36
A17: Depreciation and amortisation expense | B17: 2015.19 | C17: 2091.64 | D17: 2450.4 | E17: 2981.03 | F17: 3858.69
A18: Other expenses | B18: 10662.58 | C18: 12879.96 | D18: 16577.96 | E18: 18813.14 | F18: 24170.43
A19: Total expenses | B19: =SUM(B11:B18) -> 111752.71 | C19: =SUM(C11:C18) -> 125245.85 | D19: =SUM(D11:D18) -> 159010.19 | E19: =SUM(E11:E18) -> 199151.04 | F19: =SUM(F11:F18) -> 255069.69
A21: EBITDA (Excl. Other Income) | B21: =B6-B11-B12-B13-B14-B15-B18 -> 12651.99 | C21: =C6-C11-C12-C13-C14-C15-C18 -> 18521.14 | D21: =D6-D11-D12-D13-D14-D15-D18 -> 24918.05 | E21: =E6-E11-E12-E13-E14-E15-E18 -> 29602.4 | F21: =F6-F11-F12-F13-F14-F15-F18 -> 40057.28
A22: EBITDA Margin (%) | B22: =B21/B6 -> 0.10367288 | C22: =C21/C6 -> 0.13128318 | D22: =D21/D6 -> 0.13813092 | E22: =E21/E6 -> 0.13210455 | F22: =F21/F6 -> 0.13868428
A23: EBIT | B23: =B21-B17 -> 10636.8 | C23: =C21-C17 -> 16429.5 | D23: =D21-D17 -> 22467.65 | E23: =E21-E17 -> 26621.37 | F23: =F21-F17 -> 36198.59
A24: EBIT Margin (%) | B24: =B23/B6 -> 0.087160016 | C24: =C23/C6 -> 0.11645704 | D24: =D23/D6 -> 0.12454735 | E24: =E23/E6 -> 0.11880131 | F24: =F23/F6 -> 0.12532492
A26: Profit before Share and Tax | B26: =B23+B7-B16 -> 11184.13 | C26: =C23+C7-C16 -> 17165.19 | D26: =D23+D7-D16 -> 23593 | E26: =E23+E7-E16 -> 27008.45 | F26: =F23+F7-F16 -> 36130.75
A27: Share of profit / (loss) of joint venture (net of tax) | B27: -25.55 | C27: -92.63 | D27: 0 | E27: 0 | F27: 0
A28: Profit before tax (PBT) | B28: =B26+B27 -> 11158.58 | C28: =C26+C27 -> 17072.56 | D28: =D26+D27 -> 23593 | E28: =E26+E27 -> 27008.45 | F28: =F26+F27 -> 36130.75
A29: Tax Expenses
A30: Current tax | B30: 2809.27 | C30: 4060.5 | D30: 5535.25 | E30: 6154.98 | F30: 9390.58
A31: Deferred tax | B31: -103 | C31: 181.2 | D31: 28.58 | E31: 398.1 | F31: -344.1
A32: Total Tax Expenses | B32: =SUM(B30:B31) -> 2706.27 | C32: =SUM(C30:C31) -> 4241.7 | D32: =SUM(D30:D31) -> 5563.83 | E32: =SUM(E30:E31) -> 6553.08 | F32: =SUM(F30:F31) -> 9046.48
A34: Profit After Tax (PAT) | B34: =B28-B32 -> 8452.31 | C34: =C28-C32 -> 12830.86 | D34: =D28-D32 -> 18029.17 | E34: =E28-E32 -> 20455.37 | F34: =F28-F32 -> 27084.27
A35: Net Profit Margin (%) | B35: =B34/B6 -> 0.069259878 | C35: =C34/C6 -> 0.090948837 | D35: =D34/D6 -> 0.099943047 | E35: =E34/E6 -> 0.091284739 | F35: =F34/F6 -> 0.093769786
A39: Key Historical Indicators
A40: Metric | B40: FY22 | C40: FY23 | D40: FY24 | E40: FY25 | F40: FY26 | G40: YoY Growth | H40: 4-Yr CAGR
A41: Net Sales / Revenue | B41: ='Income Statement'!B6 -> 122037.61 | C41: ='Income Statement'!C6 -> 141077.78 | D41: ='Income Statement'!D6 -> 180394.44 | E41: ='Income Statement'!E6 -> 224083.13 | F41: ='Income Statement'!F6 -> 288837.92 | G41: =(F41-E41)/E41 -> 0.28897664 | H41: =(F41/B41)^(1/4)-1 -> 0.24033823
A42: EBITDA | B42: ='Income Statement'!B21 -> 12651.99 | C42: ='Income Statement'!C21 -> 18521.14 | D42: ='Income Statement'!D21 -> 24918.05 | E42: ='Income Statement'!E21 -> 29602.4 | F42: ='Income Statement'!F21 -> 40057.28 | G42: =(F42-E42)/E42 -> 0.35317677 | H42: =(F42/B42)^(1/4)-1 -> 0.33392267
A43: Profit After Tax (PAT) | B43: ='Income Statement'!B34 -> 8452.31 | C43: ='Income Statement'!C34 -> 12830.86 | D43: ='Income Statement'!D34 -> 18029.17 | E43: ='Income Statement'!E34 -> 20455.37 | F43: ='Income Statement'!F34 -> 27084.27 | G43: =(F43-E43)/E43 -> 0.32406649 | H43: =(F43/B43)^(1/4)-1 -> 0.33793628
A44: Shareholders Networth | B44: ='Balance Sheet'!B38 -> 55437.41 | C44: ='Balance Sheet'!C38 -> 66311.37 | D44: ='Balance Sheet'!D38 -> 81871.34 | E44: ='Balance Sheet'!E38 -> 98280.55 | F44: ='Balance Sheet'!F38 -> 120085.76 | G44: =(F44-E44)/E44 -> 0.22186699 | H44: =(F44/B44)^(1/4)-1 -> 0.21317135

Sheet Balance Sheet
A1: Polycab India Limited
A2: Consolidated Balance Sheet (FY22 - FY26)
A4: Line Item | B4: FY22 | C4: FY23 | D4: FY24 | E4: FY25 | F4: FY26
A5: ASSETS
A6: Non-current assets
A7: Property, plant and equipment (Net) | B7: 16170.25 | C7: 20104.28 | D7: 21677.57 | E7: 27913.26 | F7: 35050.71
A8: Capital work-in-progress | B8: 3754.5 | C8: 2507.67 | D8: 5784.46 | E8: 7081.44 | F8: 11392.59
A9: Investment property under construction | B9: 0 | C9: 0 | D9: 762.98 | E9: 790.08 | F9: 883.02
A10: Right of use assets | B10: 351.36 | C10: 361.82 | D10: 728.26 | E10: 1309.71 | F10: 1426.27
A11: Goodwill | B11: 46.22 | C11: 46.22 | D11: 46.22 | E11: 0 | F11: 0
A12: Other intangible assets | B12: 183.4 | C12: 157.08 | D12: 160.17 | E12: 98.45 | F12: 40.97
A13: Investments accounted for using equity method | B13: 92.63 | C13: 0 | D13: 0 | E13: 0 | F13: 0
A14: Non-current Trade receivables | B14: 799.31 | C14: 526.37 | D14: 1190.7 | E14: 2994.38 | F14: 4477.84
A15: Other non-current financial assets | B15: 166.52 | C15: 70.4 | D15: 311.34 | E15: 712.41 | F15: 571.94
A16: Non-current tax assets (net) | B16: 479.46 | C16: 251.89 | D16: 297.08 | E16: 503.73 | F16: 558.74
A17: Deferred tax assets (net) | B17: 0.09 | C17: 13.45 | D17: 128.69 | E17: 270.7 | F17: 116.02
A18: Other non-current assets | B18: 663.96 | C18: 1128.09 | D18: 2561.76 | E18: 2893.54 | F18: 3638.74
A19: Total non-current assets | B19: =SUM(B7:B18) -> 22707.7 | C19: =SUM(C7:C18) -> 25167.27 | D19: =SUM(D7:D18) -> 33649.23 | E19: =SUM(E7:E18) -> 44567.7 | F19: =SUM(F7:F18) -> 58156.84
A21: Current assets
A22: Inventories | B22: 21996.47 | C22: 29513.84 | D22: 36751.14 | E22: 36613 | F22: 55595.98
A23: Current Investments | B23: 7640.51 | C23: 13504.95 | D23: 18224.17 | E23: 17490.42 | F23: 34048.23
A24: Current Trade receivables | B24: 12963.94 | C24: 12465.96 | D24: 20471.17 | E24: 25962.68 | F24: 37585.04
A25: Cash and cash equivalents | B25: 1216.91 | C25: 1527.52 | D25: 3070.31 | E25: 2173.87 | F25: 3903.43
A26: Bank balances other than cash and cash equivalents | B26: 2854.27 | C26: 5424.91 | D26: 953.27 | E26: 5532.49 | F26: 4921.27
A27: Loans - Current | B27: 126.8 | C27: 103.47 | D27: 106.26 | E27: 111 | F27: 112.31
A28: Other current financial assets | B28: 259.37 | C28: 295.91 | D28: 335.52 | E28: 1147.49 | F28: 2632.57
A29: Other current assets | B29: 4188.67 | C29: 6250.93 | D29: 7227.77 | E29: 4159.01 | F29: 7780.05
A30: Total current assets | B30: =SUM(B22:B29) -> 51246.94 | C30: =SUM(C22:C29) -> 69087.49 | D30: =SUM(D22:D29) -> 87139.61 | E30: =SUM(E22:E29) -> 93189.96 | F30: =SUM(F22:F29) -> 146578.88
A31: Non-current assets classified as held for sale | B31: 0 | C31: 0 | D31: 0 | E31: 0 | F31: 26.18
A32: TOTAL ASSETS | B32: =B19+B30+B31 -> 73954.64 | C32: =C19+C30+C31 -> 94254.76 | D32: =D19+D30+D31 -> 120788.84 | E32: =E19+E30+E31 -> 137757.66 | F32: =F19+F30+F31 -> 204761.9
A34: EQUITY AND LIABILITIES
A35: Equity
A36: Equity share capital | B36: 1494.43 | C36: 1497.65 | D36: 1502.36 | E36: 1504.26 | F36: 1505.51
A37: Other equity | B37: 53942.98 | C37: 64813.72 | D37: 80368.98 | E37: 96776.29 | F37: 118580.25
A38: Total Shareholders Networth | B38: =SUM(B36:B37) -> 55437.41 | C38: =SUM(C36:C37) -> 66311.37 | D38: =SUM(D36:D37) -> 81871.34 | E38: =SUM(E36:E37) -> 98280.55 | F38: =SUM(F36:F37) -> 120085.76
A39: Non-controlling interests | B39: 254.56 | C39: 373.77 | D39: 562.07 | E39: 817.69 | F39: 1181.93
A40: Total Equity | B40: =B38+B39 -> 55691.97 | C40: =C38+C39 -> 66685.14 | D40: =D38+D39 -> 82433.41 | E40: =E38+E39 -> 99098.24 | F40: =F38+F39 -> 121267.69
A42: Non-current liabilities
A43: Long-term borrowings | B43: 0 | C43: 68.51 | D43: 226.04 | E43: 419.4 | F43: 392.67
A44: Lease liabilities - Non-current | B44: 0 | C44: 224.33 | D44: 244.96 | E44: 709.34 | F44: 803.72
...

Sheet Forensic & Ratio Analysis
A1: Polycab India Limited
A2: Forensic Auditing Checks and Key Performance Ratios (FY22 - FY26)
A4: Line Item | B4: FY22 | C4: FY23 | D4: FY24 | E4: FY25 | F4: FY26
A5: FORENSIC RED FLAG CHECKS
A6: 1. Cash Flow Backing of PAT (CFO / PAT Ratio)
A7: Cash Flow from Operations (CFO) | B7: 5116.11 | C7: 14275.21 | D7: 12962.4 | E7: 18097.89 | F7: 21151.04
A8: Profit After Tax (PAT) | B8: ='Income Statement'!B34 -> 8452.31 | C8: ='Income Statement'!C34 -> 12830.86 | D8: ='Income Statement'!D34 -> 18029.17 | E8: ='Income Statement'!E34 -> 20455.37 | F8: ='Income Statement'!F34 -> 27084.27
A9: CFO / PAT Ratio (Target > 1.0x) | B9: =B7/B8 -> 0.60529133 | C9: =C7/C8 -> 1.1125684 | D9: =D7/D8 -> 0.71896821 | E9: =E7/E8 -> 0.88475007 | F9: =F7/F8 -> 0.78093447
A10: Forensic Trigger? (If < 0.8x) | B10: =IF(B9<0.8,"WARNING: Weak Cash Generation","PASS: Strong Cash Backing") -> WARNING: Weak Cash Generation | C10: =IF(C9<0.8,"WARNING: Weak Cash Generation","PASS: Strong Cash Backing") -> PASS: Strong Cash Backing | D10: =IF(D9<0.8,"WARNING: Weak Cash Generation","PASS: Strong Cash Backing") -> WARNING: Weak Cash Generation | E10: =IF(E9<0.8,"WARNING: Weak Cash Generation","PASS: Strong Cash Backing") -> PASS: Strong Cash Backing | F10: =IF(F9<0.8,"WARNING: Weak Cash Generation","PASS: Strong Cash Backing") -> WARNING: Weak Cash Generation
A12: 2. Trade Receivables vs. Revenue Momentum
A13: Revenue YoY Growth | B13: =IFERROR(('Income Statement'!B6-'Income Statement'!B6)/'Income Statement'!B6, 0) -> 0 | C13: =IFERROR(('Income Statement'!C6-'Income Statement'!B6)/'Income Statement'!B6, 0) -> 0.15601887 | D13: =IFERROR(('Income Statement'!D6-'Income Statement'!C6)/'Income Statement'!C6, 0) -> 0.27868783 | E13: =IFERROR(('Income Statement'!E6-'Income Statement'!D6)/'Income Statement'!D6, 0) -> 0.24218424 | F13: =IFERROR(('Income Statement'!F6-'Income Statement'!E6)/'Income Statement'!E6, 0) -> 0.28897664
A14: Trade Receivables (Current + Non-current) | B14: ='Balance Sheet'!B14+'Balance Sheet'!B24 -> 13763.25 | C14: ='Balance Sheet'!C14+'Balance Sheet'!C24 -> 12992.33 | D14: ='Balance Sheet'!D14+'Balance Sheet'!D24 -> 21661.87 | E14: ='Balance Sheet'!E14+'Balance Sheet'!E24 -> 28957.06 | F14: ='Balance Sheet'!F14+'Balance Sheet'!F24 -> 42062.88
A15: Receivables YoY Growth | B15: =IFERROR((B14-B14)/B14, 0) -> 0 | C15: =IFERROR((C14-B14)/B14, 0) -> -0.056012933 | D15: =IFERROR((D14-C14)/C14, 0) -> 0.66728139 | E15: =IFERROR((E14-D14)/D14, 0) -> 0.33677563 | F15: =IFERROR((F14-E14)/E14, 0) -> 0.45259498
A16: Receivable days (Average) | B16: =IFERROR((B14/'Income Statement'!B6)*365,0) -> 41.164246 | C16: =IFERROR((C14/'Income Statement'!C6)*365,0) -> 33.614085 | D16: =IFERROR((D14/'Income Statement'!D6)*365,0) -> 43.829414 | E16: =IFERROR((E14/'Income Statement'!E6)*365,0) -> 47.166991 | F16: =IFERROR((F14/'Income Statement'!F6)*365,0) -> 53.154209
A17: Receivable Growth Outpaces Revenue? | B17: =IF(B15>(B13+0.1),"WATCH: Receivables growing faster","OK: Controlled Receivables") -> OK: Controlled Receivables | C17: =IF(C15>(C13+0.1),"WATCH: Receivables growing faster","OK: Controlled Receivables") -> OK: Controlled Receivables | D17: =IF(D15>(D13+0.1),"WATCH: Receivables growing faster","OK: Controlled Receivables") -> WATCH: Receivables growing faster | E17: =IF(E15>(E13+0.1),"WATCH: Receivables growing faster","OK: Controlled Receivables") -> OK: Controlled Receivables | F17: =IF(F15>(F13+0.1),"WATCH: Receivables growing faster","OK: Controlled Receivables") -> WATCH: Receivables growing faster
A19: 3. Inventory Days & Cost of Materials Mismatch
A20: Cost of Materials Consumed Growth | B20: =IFERROR(('Income Statement'!B11-'Income Statement'!B11)/'Income Statement'!B11, 0) -> 0 | C20: =IFERROR(('Income Statement'!C11-'Income Statement'!B11)/'Income Statement'!B11, 0) -> 0.06159131 | D20: =IFERROR(('Income Statement'!D11-'Income Statement'!C11)/'Income Statement'!C11, 0) -> 0.29581365 | E20: =IFERROR(('Income Statement'!E11-'Income Statement'!D11)/'Income Statement'!D11, 0) -> 0.21764847 | F20: =IFERROR(('Income Statement'!F11-'Income Statement'!E11)/'Income Statement'!E11, 0) -> 0.33717119
A21: Inventories (Balance Sheet) | B21: ='Balance Sheet'!B22 -> 21996.47 | C21: ='Balance Sheet'!C22 -> 29513.84 | D21: ='Balance Sheet'!D22 -> 36751.14 | E21: ='Balance Sheet'!E22 -> 36613 | F21: ='Balance Sheet'!F22 -> 55595.98
A22: Inventory YoY Growth | B22: =IFERROR((B21-B21)/B21,0) -> 0 | C22: =IFERROR((C21-B21)/B21,0) -> 0.34175347 | D22: =IFERROR((D21-C21)/C21,0) -> 0.24521716 | E22: =IFERROR((E21-D21)/D21,0) -> -0.003758795 | F22: =IFERROR((F21-E21)/E21,0) -> 0.5184765
A23: Inventory days (Average) | B23: =IFERROR((B21/'Income Statement'!B11)*365,0) -> 87.22828 | C23: =IFERROR((C21/'Income Statement'!C11)*365,0) -> 110.2485 | D23: =IFERROR((D21/'Income Statement'!D11)*365,0) -> 105.94372 | E23: =IFERROR((E21/'Income Statement'!E11)*365,0) -> 86.67978 | F23: =IFERROR((F21/'Income Statement'!F11)*365,0) -> 98.432579
A24: Inventory Growth Outpaces Materials Cost? | B24: =IF(B22>(B20+0.1),"WATCH: Inventories piling up","OK: Efficient Turnover") -> OK: Efficient Turnover | C24: =IF(C22>(C20+0.1),"WATCH: Inventories piling up","OK: Efficient Turnover") -> WATCH: Inventories piling up | D24: =IF(D22>(D20+0.1),"WATCH: Inventories piling up","OK: Efficient Turnover") -> OK: Efficient Turnover | E24: =IF(E22>(E20+0.1),"WATCH: Inventories piling up","OK: Efficient Turnover") -> OK: Efficient Turnover | F24: =IF(F22>(F20+0.1),"WATCH: Inventories piling up","OK: Efficient Turnover") -> WATCH: Inventories piling up
A26: KEY FINANCIAL RATIOS
A27: Solvency & Liquidity
A28: Current Ratio (Liquidity) | B28: ='Balance Sheet'!B30/'Balance Sheet'!B61 -> 2.3211031 | C28: ='Balance Sheet'!C30/'Balance Sheet'!C61 -> 2.9534249 | D28: ='Balance Sheet'!D30/'Balance Sheet'!D61 -> 2.4547932 | E28: ='Balance Sheet'!E30/'Balance Sheet'!E61 -> 2.6548742 | F28: ='Balance Sheet'!F30/'Balance Sheet'!F61 -> 1.8402309
A29: Debt-to-Equity Ratio (Leverage) | B29: =IFERROR(('Balance Sheet'!B43+'Balance Sheet'!B52)/('Balance Sheet'!B38), 0) -> 0.014814004 | C29: =IFERROR(('Balance Sheet'!C43+'Balance Sheet'!C52)/('Balance Sheet'!C38), 0) -> 0.023794713 | D29: =IFERROR(('Balance Sheet'!D43+'Balance Sheet'!D52)/('Balance Sheet'!D38), 0) -> 0.010965254 | E29: =IFERROR(('Balance Sheet'!E43+'Balance Sheet'!E52)/('Balance Sheet'!E38), 0) -> 0.011091106 | F29: =IFERROR(('Balance Sheet'!F43+'Balance Sheet'!F52)/('Balance Sheet'!F38), 0) -> 0.011032948
A30: Gearing Ratio (%) | B30: =IFERROR(('Balance Sheet'!B43+'Balance Sheet'!B52)/('Balance Sheet'!B38+B43+B52), 0) -> 0.014814004 | C30: =IFERROR(('Balance Sheet'!C43+'Balance Sheet'!C52)/('Balance Sheet'!C38+C43+C52), 0) -> 0.023794713 | D30: =IFERROR(('Balance Sheet'!D43+'Balance Sheet'!D52)/('Balance Sheet'!D38+D43+D52), 0) -> 0.010965254 | E30: =IFERROR(('Balance Sheet'!E43+'Balance Sheet'!E52)/('Balance Sheet'!E38+E43+E52), 0) -> 0.011091106 | F30: =IFERROR(('Balance Sheet'!F43+'Balance Sheet'!F52)/('Balance Sheet'!F38+F43+F52), 0) -> 0.011032948
A31: Interest Coverage Ratio (x) | B31: =IFERROR('Income Statement'!B23/'Income Statement'!B16, 0) -> 30.226769 | C31: =IFERROR('Income Statement'!C23/'Income Statement'!C16, 0) -> 27.49385 | D31: =IFERROR('Income Statement'!D23/'Income Statement'!D16, 0) -> 20.738093 | E31: =IFERROR('Income Statement'!E23/'Income Statement'!E16, 0) -> 15.759004 | F31: =IFERROR('Income Statement'!F23/'Income Statement'!F16, 0) -> 14.894333
A33: Return / Profitability
A34: Return on Equity (RoE %) | B34: =IFERROR('Income Statement'!B34/'Balance Sheet'!B38, 0) -> 0.15246582 | C34: =IFERROR('Income Statement'!C34/'Balance Sheet'!C38, 0) -> 0.19349412 | D34: =IFERROR('Income Statement'!D34/'Balance Sheet'!D38, 0) -> 0.22021345 | E34: =IFERROR('Income Statement'!E34/'Balance Sheet'!E38, 0) -> 0.20813243 | F34: =IFERROR('Income Statement'!F34/'Balance Sheet'!F38, 0) -> 0.22554106
A35: Return on Capital Employed (RoCE %) | B35: =IFERROR('Income Statement'!B23/('Balance Sheet'!B38+B43+B52), 0) -> 0.19187044 | C35: =IFERROR('Income Statement'!C23/('Balance Sheet'!C38+C43+C52), 0) -> 0.24776294 | D35: =IFERROR('Income Statement'!D23/('Balance Sheet'!D38+D43+D52), 0) -> 0.27442631 | E35: =IFERROR('Income Statement'!E23/('Balance Sheet'!E38+E43+E52), 0) -> 0.27087119 | F35: =IFERROR('Income Statement'!F23/('Balance Sheet'!F38+F43+F52), 0) -> 0.30143949

Sheet Notes to Accounts Linkages
A1: Polycab India Limited
A2: Notes to Accounts - Key Footnote Linkages to Financial Statements (FY22 - FY26)
A4: Note / Balance Sheet & P&L Linkages | B4: FY22 | C4: FY23 | D4: FY24 | E4: FY25 | F4: FY26
A5: Note 3: Property, Plant & Equipment (PPE) & Capex Commitments
A6: Property, Plant and Equipment (Net carrying value) | B6: ='Balance Sheet'!B7 -> 16170.25 | C6: ='Balance Sheet'!C7 -> 20104.28 | D6: ='Balance Sheet'!D7 -> 21677.57 | E6: ='Balance Sheet'!E7 -> 27913.26 | F6: ='Balance Sheet'!F7 -> 35050.71
A7: Capital Work-in-Progress (CWIP) | B7: ='Balance Sheet'!B8 -> 3754.5 | C7: ='Balance Sheet'!C8 -> 2507.67 | D7: ='Balance Sheet'!D8 -> 5784.46 | E7: ='Balance Sheet'!E8 -> 7081.44 | F7: ='Balance Sheet'!F8 -> 11392.59
A8: Investment Property under Construction | B8: ='Balance Sheet'!B9 -> 0 | C8: ='Balance Sheet'!C9 -> 0 | D8: ='Balance Sheet'!D9 -> 762.98 | E8: ='Balance Sheet'!E9 -> 790.08 | F8: ='Balance Sheet'!F9 -> 883.02
A9: Total Property, Plant & Equipment Carrying Value | B9: =SUM(B6:B8) -> 19924.75 | C9: =SUM(C6:C8) -> 22611.95 | D9: =SUM(D6:D8) -> 28225.01 | E9: =SUM(E6:E8) -> 35784.78 | F9: =SUM(F6:F8) -> 47326.32
A11: Capital Commitments (Contracted but not provided, net of advances) | B11: 2281.66 | C11: 4285.95 | D11: 10575.3 | E11: 2515.59 | F11: 14799
A13: Note 8: Trade Receivables Current/Non-current & Expected Credit Loss (ECL)
A14: Current Trade Receivables (Net) | B14: ='Balance Sheet'!B24 -> 12963.94 | C14: ='Balance Sheet'!C24 -> 12465.96 | D14: ='Balance Sheet'!D24 -> 20471.17 | E14: ='Balance Sheet'!E24 -> 25962.68 | F14: ='Balance Sheet'!F24 -> 37585.04
A15: Non-Current Trade Receivables (Net) | B15: ='Balance Sheet'!B14 -> 799.31 | C15: ='Balance Sheet'!C14 -> 526.37 | D15: ='Balance Sheet'!D14 -> 1190.7 | E15: ='Balance Sheet'!E14 -> 2994.38 | F15: ='Balance Sheet'!F14 -> 4477.84
A16: Less: Impairment Allowance for doubtful debts (Cumulative ECL) | B16: -1249.16 | C16: -1163.08 | D16: -1352.68 | E16: -1267.03 | F16: -1185.31
A17: Total Gross Trade Receivables before ECL | B17: =B14+B15-B16 -> 15012.41 | C17: =C14+C15-C16 -> 14155.41 | D17: =D14+D15-D16 -> 23014.55 | E17: =E14+E15-E16 -> 30224.09 | F17: =F14+F15-F16 -> 43248.19
A19: Note 21: Acceptances under Trade Payables (Usance Letters of Credit)
A20: Acceptances (Trade Payables - Current) | B20: ='Balance Sheet'!B54 -> 12257.56 | C20: ='Balance Sheet'!C54 -> 12257.56 | D20: ='Balance Sheet'!D54 -> 18619.66 | E20: ='Balance Sheet'!E54 -> 13062.37 | F20: ='Balance Sheet'!F54 -> 42656.19
A21: Acceptances as a % of Total Current Liabilities | B21: =B20/'Balance Sheet'!B61 -> 0.5551758 | C21: =C20/'Balance Sheet'!C61 -> 0.52399911 | D21: =D20/'Balance Sheet'!D61 -> 0.52453086 | E21: =E20/'Balance Sheet'!E61 -> 0.37213181 | F21: =F20/'Balance Sheet'!F61 -> 0.53552898
A23: Note 20: Lease Liabilities (Under Ind AS 116)
A24: Lease Liabilities - Current (Amortised Cost) | B24: ='Balance Sheet'!B53 -> 103.34 | C24: ='Balance Sheet'!C53 -> 138.96 | D24: ='Balance Sheet'!D53 -> 468.23 | E24: ='Balance Sheet'!E53 -> 224.99 | F24: ='Balance Sheet'!F53 -> 226.55
A25: Lease Liabilities - Non-Current (Amortised Cost) | B25: ='Balance Sheet'!B44 -> 0 | C25: ='Balance Sheet'!C44 -> 224.33 | D25: ='Balance Sheet'!D44 -> 244.96 | E25: ='Balance Sheet'!E44 -> 709.34 | F25: ='Balance Sheet'!F44 -> 803.72
A26: Total Lease Liabilities Outstanding | B26: =SUM(B24:B25) -> 103.34 | C26: =SUM(C24:C25) -> 363.29 | D26: =SUM(D24:D25) -> 713.19 | E26: =SUM(E24:E25) -> 934.33 | F26: =SUM(F24:F25) -> 1030.27
A28: Note 37/39: Related Parties & Strategic Disclosures
A29: Impairment of Receivables from Joint Venture (TEPL) | B29: 0 | C29: 0 | D29: 0 | E29: 0 | F29: 270
A30: Actual Corporate Social Responsibility (CSR) Spend | B30: 191.89 | C30: 224.79 | D30: 259.01 | E30: 180.31 | F30: 444.42
A31: Finance Costs from P&L (For audit reference) | B31: ='Income Statement'!B16 -> 351.9 | C31: ='Income Statement'!C16 -> 597.57 | D31: ='Income Statement'!D16 -> 1083.4 | E31: ='Income Statement'!E16 -> 1689.28 | F31: ='Income Statement'!F16 -> 2430.36

Sheet MD&A Strategic Analysis
A1: Polycab India Limited
A2: Management Discussion & Analysis (MD&A) - Strategic Longitudinal Analysis (FY22 - FY26)
A4: Operational Segment / Strategic Pillar | B4: Key Discussion Points, Initiatives and Operational Evolution over 5 Years
A5: Project LEAP (FY21-FY25 Strategic Blueprint) | B5: • Reached the foundational revenue milestone of ₹200 billion in FY25, a full year ahead of the initially targeted FY26 deadline. • Successfully implemented pivotal enablers including the merger of Heavy Duty Cables (HDC) and Light Duty Cables (LDC) segments to drive operational and cross-selling synergies. • Executed a consumer price laddering strategy in the domestic Wires segment to expand affordability and capture wide market segments. • Realized a substantial expansion of the net cash position from ₹9.6B in FY21 to ₹24.5B in FY25, driving massive balance sheet resilience.
A6: Project Spring (FY26-FY30 Growth Horizon Plan) | B6: • Launched as the successor multi-year roadmap focused on capitalizing on the Indian infrastructure upcycle and growing global W&C demand. • Set clear guided targets: grow core Cables & Wires segment at 1.5x the industry growth rate and maintain EBITDA margins within 11-13%. • Outlined a robust Capex program of ₹60-80 billion to support capacity expansion, smart manufacturing, and ESG integration. • Target of exports contributing greater than 10% to total consolidated revenues, transitioning exports from institutional-led to distribution-led.
A7: Wires & Cables (W&C) (Segment Leadership & Scale) | B7: • Retained absolute market leadership in the Indian organized Cable & Wires sector, expanding market share to 30-31% in FY26. • Leveraged the power, infrastructure, real estate, and public capex upcycle. Primary driver of top-line expansion, surpassing ₹188B in FY25. • Deployed Automated High Voltage and Continuity Testing machinery at manufacturing sites to ensure global-grade product safety. • Spearheaded B2C transition through micromarket analytics, shifting the portfolio mix and optimizing distributor margins.
A8: FMEG Turnaround Story (Operational Restructuring) | B8: • Restructured operations following execution bottlenecks in FY23 by establishing distinct, product-focused units (merging Fans with Lights, and Retail Wires with Switches). • Reached a crucial operational break-even in late Q4 FY25, following ten consecutive quarters of losses due to massive initial spends in brand building, distribution, and R&D. • Maintained 5 consecutive quarters of solid profitability in FY26, supporting bottom-line expansions. • Guided to grow at 1.5x to 2x the market growth rate under Project Spring, targeting long-term EBITDA margins of 8% to 10%.
A9: Backward Integration (Margin Defensive Moat) | B9: • Maintained a high degree of backward integration, capturing captive manufacturing of aluminum and copper rods in-house. • Serves as an extremely powerful defensive moat that shields operational EBITDA margins from raw material commodity price volatility. • Supports highly competitive pricing capabilities in domestic tenders and protects margins in large-scale infrastructure and utility projects.

Sheet ESG Performance (BRSR)
A1: Polycab India Limited
A2: ESG (Environmental, Social, & Governance) Performance KPIs Tracking (FY22 - FY26)
A4: ESG Key Performance Indicators | B4: FY22 | C4: FY23 | D4: FY24 | E4: FY25 | F4: FY26 | G4: 2030 Target & Direction
A5: ENVIRONMENTAL STEWARDSHIP
A6: Renewable Electricity Consumed (GJ) | B6: 94483 | C6: 124136 | D6: 126522 | E6: 157554 | F6: 193461 | G6: Increase Renewable Energy Mix
A7: Renewable Share in Total Electricity (%) | B7: 0.155 | C7: 0.17 | D7: 0.17 | E7: 0.17 | F7: 0.183 | G7: 50.0% by FY30 (On Track)
A8: Total Scope 1 Emissions (MTCO2e) | B8: 5000 | C8: 6528 | D8: 22568 | E8: 29061 | F8: 31710 | G8: Decarbonise Direct Operations
A9: Total Scope 2 Emissions (MTCO2e) | B9: 105053 | C9: 123181 | D9: 156937 | E9: 155118 | F9: 169691 | G9: Reduce Grid Dependency
A10: Total Scope 1 & 2 Emissions (MTCO2e) | B10: =SUM(B8:B9) -> 110053 | C10: =SUM(C8:C9) -> 129709 | D10: =SUM(D8:D9) -> 179505 | E10: =SUM(E8:E9) -> 184179 | F10: =SUM(F8:F9) -> 201401 | G10: Combined Footprint
A11: Scope 1 & 2 Emission Intensity (MTCO2e / H Cr) | B11: 8.68 | C11: 9.32 | D11: 9.94 | E11: 8.4 | F11: 7.14 | G11: Target: Significant Reduction (Achieved 15% reduction in FY26)
A12: Total Water Consumption (KL) | B12: 680000 | C12: 762603 | D12: 752000 | E12: 412000 | F12: 407443 | G12: 30% Recycled Water usage
A13: Total Waste Recycled (MT) | B13: 11000 | C13: 12000 | D13: 14500 | E13: 19220 | F13: 18357 | G13: Zero Waste to Landfill
A14: Inputs Sourced from Sustainable Sources (% by val) | B14: 0.65 | C14: 0.7 | D14: 0.75 | E14: 0.8 | F14: 0.836 | G14: 100.0% Strategic Supplier assessment
A15: SOCIAL & COMMUNITY WELL-BEING
A16: Actual Corporate Social Responsibility (CSR) Spend | B16: ='Notes to Accounts Linkages'!B30 -> 191.89 | C16: ='Notes to Accounts Linkages'!C30 -> 224.79 | D16: ='Notes to Accounts Linkages'!D30 -> 259.01 | E16: ='Notes to Accounts Linkages'!E30 -> 180.31 | F16: ='Notes to Accounts Linkages'!F30 -> 444.42 | G16: Commitment to Local Communities
A17: Total Lives Impacted via CSR (Cumulative, Million) | B17: 0.05 | C17: 0.1 | D17: 0.235 | E17: 0.235 | F17: 0.507 | G17: Touch 1.0 million lives by 2030
A18: Employee & Worker LTIFR (Loss Time Injury Rate) | B18: 0.1 | C18: 0.09 | D18: 0.085 | E18: 0.075 | F18: 0.067 | G18: Zero Fatalities and High-Consequence Injuries
A19: Women Representation in Senior Leadership (%) | B19: 0.035 | C19: 0.041 | D19: 0.045 | E19: 0.051 | F19: 0.053 | G19: Target 11.0% women employees
A20: CORPORATE GOVERNANCE
A21: Board Independence (%) | B21: 0.5 | C21: 0.5 | D21: 0.5 | E21: 0.55 | F21: 0.56 | G21: Strong Independent Board Oversight
A22: Committees Led by Independent Directors (%) | B22: 1 | C22: 1 | D22: 1 | E22: 1 | F22: 1 | G22: 100.0% Oversight Alignment
A23: Shareholder complaints resolved (%) | B23: 1 | C23: 1 | D23: 1 | E23: 1 | F23: 1 | G23: 100.0% Redressal (Always Resolved)
